<?xml version="1.0"?>
<robot xmlns:xacro="http://www.ros.org/wiki/xacro">
    
    <!-- BASE_LINK -->
    <link name="base_footprint">
       <origin xyz="0.0 0.0 0.0"/>
    </link>

    <joint name="base_joint" type="fixed">
        <origin xyz="0.0 0.0 0.1"/>
        <parent link="base_footprint"/>
        <child link="base_link"/>
    </joint>

    <link name="base_link">
       <origin xyz="0.0 0.0 0.0"/>
    </link>

    <!-- CHASSIS_LINK -->

    <joint name="chassis_joint" type="fixed">
        <parent link="base_link"/>
        <child link="chassis"/>
        <origin xyz="-0.1 0.0 0.0"/>
    </joint>

    <link name="chassis">
        <inertial>
            <origin xyz="0.2 0.0 0.1" rpy="0.0 0.0 0.0"/>
            <mass value="10.0"/>
            <inertia ixx="0.1" ixy="0.0" ixz="0.0" iyy="0.1" iyz="0.0" izz="0.1"/>
        </inertial>
        <visual>
            <origin xyz="0.2 0.0 0.1" rpy="0.0 0.0 0.0"/>
            <geometry>
                <box size="0.4 0.4 0.2"/>
            </geometry>
            <material name="blue"/>
        </visual>
        <collision>
            <origin xyz="0.2 0.0 0.1" rpy="0.0 0.0 0.0"/>
            <geometry>
                <box size="0.4 0.4 0.2"/>
            </geometry>
        </collision>
    </link>

    <gazebo reference="chassis">
        <material>Gazebo/Blue</material>
    </gazebo>

    <!-- LEFT WHEEL LINK -->
    <joint name="left_wheel_joint" type="continuous">
        <origin xyz="0 0.22 0" rpy="-${pi/2} 0.0 0.0"/>
        <parent link="base_link"/>
        <child link="left_wheel"/>
        <axis xyz="0.0 0.0 1.0"/>
    </joint> 

    <link name="left_wheel">
        <visual>
            <origin xyz="0.0 0.0 0.0" rpy="0.0 0.0 0.0"/>
            <geometry>
                <cylinder radius="0.1" length="0.04"/>
            </geometry>
            <material name="black"/>
        </visual>
        <collision>
            <origin xyz="0.0 0.0 0.0" rpy="0.0 0.0 0.0"/>
            <geometry>
                <cylinder radius="0.1" length="0.04"/>
            </geometry>
        </collision>
        <inertial>
            <mass value="0.5"/>
            <inertia ixx="0.1" ixy="0.0" ixz="0.0" iyy="0.1" iyz="0.0" izz="0.1"/>
        </inertial>
    </link>

    <gazebo reference="left_wheel">
        <material>Gazebo/FlatBlack</material>
    </gazebo>

    <!-- RIGHT WHEEL LINK -->
    <joint name="right_wheel_joint" type="continuous">
        <origin xyz="0 -0.22 0" rpy="${pi/2} 0.0 0.0"/>
        <parent link="base_link"/>
        <child link="right_wheel"/>
        <axis xyz="0.0 0.0 -1.0"/>
    </joint> 

    <link name="right_wheel">
        <visual>
            <origin xyz="0.0 0.0 0.0" rpy="0.0 0.0 0.0"/>
            <geometry>
                <cylinder radius="0.1" length="0.04"/>
            </geometry>
            <material name="black"/>
        </visual>
        <collision>
            <origin xyz="0.0 0.0 0.0" rpy="0.0 0.0 0.0"/>
            <geometry>
                <cylinder radius="0.1" length="0.04"/>
            </geometry>
        </collision>
        <inertial>
            <mass value="0.5"/>
            <inertia ixx="0.1" ixy="0.0" ixz="0.0" iyy="0.1" iyz="0.0" izz="0.1"/>
        </inertial>
    </link>

    <gazebo reference="right_wheel">
        <material>Gazebo/FlatBlack</material>
    </gazebo>

    <!-- CASTER_WHEEL -->
    <joint name="caster_wheel_joint" type="fixed">
        <parent link="chassis"/>
        <child link="caster_wheel"/>
        <origin xyz="0.3 0.0 0.0"/>         <!--dich 0.3 theo truc x ke tu tam cua chassis-->
    </joint>

    <link name="caster_wheel">
        <visual>
            <geometry>
                <sphere radius="0.1"/>
            </geometry>
            <material name="black"/>
        </visual>
        <collision>
            <geometry>
                <sphere radius="0.1"/>
            </geometry>
        </collision>
        <inertial>
            <mass value="0.2"/>
            <inertia ixx="0.1" ixy="0.0" ixz="0.0" iyy="0.1" iyz="0.0" izz="0.1"/>
        </inertial>
        
    </link>

    <gazebo reference="caster_wheel">
        <material>Gazebo/FlatBlack</material>
        <mu1 value="0.001"/>
        <mu2 value="0.001"/>
    </gazebo>

    <!-- lidar -->
    <joint name="joint_scan" type="fixed">
        <origin xyz="0.0 0.0 0.215" rpy="0.0 0.0 ${pi}"/>     <!--0.215 = 0.2 + 0.03/2-->
        <parent link="base_link"/>
        <child link="base_scan"/>
    </joint>

    <link name="base_scan">
        <visual>
            <geometry>
                <cylinder radius="0.04" length="0.03"/>
                <material name="orange"/>
            </geometry>
        </visual>
        <collision>
            <geometry>
                <cylinder radius="0.04" length="0.03"/>
            </geometry>
        </collision>
        <inertial>
            <mass value="0.114"/>
            <inertia ixx="0.01" ixy="0.0" ixz="0.0" iyy="0.01" iyz="0.0" izz="0.01"/>
        </inertial>
    </link>

    <gazebo reference="base_scan">
        <material>Gazebo/Orange</material>
    </gazebo>

    
    <!-- plugin lidar -->

    <!-- <gazebo reference="base_scan">
        <sensor type="ray" name="rplidar">
            <pose>0 0 0 0 0 0</pose>
            <visualize>false</visualize>
            <update_rate>40</update_rate>
            <ray>
                <scan>
                    <horizontal>
                        <samples>720</samples>
                        <resolution>1</resolution>
                        <min_angle>-2.87979</min_angle> 
                        <max_angle>2.87979</max_angle>
                    </horizontal>
                </scan>
                <range>
                    <min>0.10</min>
                    <max>20.0</max>
                    <resolution>0.01</resolution>
                </range>
                <noise>
                    <type>gaussian</type>
                    <mean>0.0</mean>
                    <stddev>0.01</stddev>
                </noise>
            </ray>
            <plugin name="gazebo_ros_head_hokuyo_controller" filename="libgazebo_ros_laser.so">
                <topicName>scan</topicName>
                <frameName>base_scan</frameName>
            </plugin>
        </sensor>
    </gazebo> -->
       
</robot>